[2024-05-03T20:03:18.530-0300] {local_task_job_runner.py:120} INFO - ::group::Pre task execution logs
[2024-05-03T20:03:18.557-0300] {taskinstance.py:2073} INFO - Dependencies all met for dep_context=non-requeueable deps ti=<TaskInstance: dag_exemplo.gera_arquivo manual__2024-05-03T23:03:03.001551+00:00 [queued]>
[2024-05-03T20:03:18.571-0300] {taskinstance.py:2073} INFO - Dependencies all met for dep_context=requeueable deps ti=<TaskInstance: dag_exemplo.gera_arquivo manual__2024-05-03T23:03:03.001551+00:00 [queued]>
[2024-05-03T20:03:18.571-0300] {taskinstance.py:2303} INFO - Starting attempt 1 of 1
[2024-05-03T20:03:18.607-0300] {taskinstance.py:2327} INFO - Executing <Task(PythonOperator): gera_arquivo> on 2024-05-03 23:03:03.001551+00:00
[2024-05-03T20:03:18.609-0300] {standard_task_runner.py:63} INFO - Started process 1223 to run task
[2024-05-03T20:03:18.611-0300] {standard_task_runner.py:90} INFO - Running: ['airflow', 'tasks', 'run', 'dag_exemplo', 'gera_arquivo', 'manual__2024-05-03T23:03:03.001551+00:00', '--job-id', '472', '--raw', '--subdir', 'DAGS_FOLDER/dag_exemplo.py', '--cfg-path', '/tmp/tmphkt7li1v']
[2024-05-03T20:03:18.612-0300] {standard_task_runner.py:91} INFO - Job 472: Subtask gera_arquivo
[2024-05-03T20:03:18.685-0300] {task_command.py:426} INFO - Running <TaskInstance: dag_exemplo.gera_arquivo manual__2024-05-03T23:03:03.001551+00:00 [running]> on host PC-Tilto.
[2024-05-03T20:03:18.838-0300] {taskinstance.py:2644} INFO - Exporting env vars: AIRFLOW_CTX_DAG_OWNER='airflow' AIRFLOW_CTX_DAG_ID='dag_exemplo' AIRFLOW_CTX_TASK_ID='gera_arquivo' AIRFLOW_CTX_EXECUTION_DATE='2024-05-03T23:03:03.001551+00:00' AIRFLOW_CTX_TRY_NUMBER='1' AIRFLOW_CTX_DAG_RUN_ID='manual__2024-05-03T23:03:03.001551+00:00'
[2024-05-03T20:03:18.839-0300] {taskinstance.py:430} INFO - ::endgroup::
[2024-05-03T20:03:18.849-0300] {taskinstance.py:441} INFO - ::group::Post task execution logs
[2024-05-03T20:03:18.849-0300] {taskinstance.py:2890} ERROR - Task failed with exception
Traceback (most recent call last):
  File "/usr/local/lib/python3.10/dist-packages/airflow/models/taskinstance.py", line 465, in _execute_task
    result = _execute_callable(context=context, **execute_callable_kwargs)
  File "/usr/local/lib/python3.10/dist-packages/airflow/models/taskinstance.py", line 432, in _execute_callable
    return execute_callable(context=context, **execute_callable_kwargs)
  File "/usr/local/lib/python3.10/dist-packages/airflow/models/baseoperator.py", line 400, in wrapper
    return func(self, *args, **kwargs)
  File "/usr/local/lib/python3.10/dist-packages/airflow/operators/python.py", line 235, in execute
    return_value = self.execute_callable()
  File "/usr/local/lib/python3.10/dist-packages/airflow/operators/python.py", line 252, in execute_callable
    return self.python_callable(*self.op_args, **self.op_kwargs)
  File "/mnt/c/Users/Tilto/Desktop/Work/Airflow/dags/dag_exemplo.py", line 11, in gera_arquivo
    with open(AIRFLOW_HOME + "data/arquivo.txt", "wb"):
FileNotFoundError: [Errno 2] No such file or directory: '/mnt/c/Users/Tilto/Desktop/Work/Airflowdata/arquivo.txt'
[2024-05-03T20:03:18.866-0300] {taskinstance.py:1205} INFO - Marking task as FAILED. dag_id=dag_exemplo, task_id=gera_arquivo, execution_date=20240503T230303, start_date=20240503T230318, end_date=20240503T230318
[2024-05-03T20:03:18.899-0300] {standard_task_runner.py:110} ERROR - Failed to execute job 472 for task gera_arquivo ([Errno 2] No such file or directory: '/mnt/c/Users/Tilto/Desktop/Work/Airflowdata/arquivo.txt'; 1223)
[2024-05-03T20:03:18.904-0300] {local_task_job_runner.py:240} INFO - Task exited with return code 1
[2024-05-03T20:03:18.928-0300] {taskinstance.py:3482} INFO - 0 downstream tasks scheduled from follow-on schedule check
[2024-05-03T20:03:18.952-0300] {local_task_job_runner.py:222} INFO - ::endgroup::
