[2024-05-04T01:28:41.780-0300] {local_task_job_runner.py:120} INFO - ::group::Pre task execution logs
[2024-05-04T01:28:41.863-0300] {taskinstance.py:2073} INFO - Dependencies all met for dep_context=non-requeueable deps ti=<TaskInstance: Hook_dag.task1 manual__2024-05-04T04:28:38.637446+00:00 [queued]>
[2024-05-04T01:28:41.894-0300] {taskinstance.py:2073} INFO - Dependencies all met for dep_context=requeueable deps ti=<TaskInstance: Hook_dag.task1 manual__2024-05-04T04:28:38.637446+00:00 [queued]>
[2024-05-04T01:28:41.895-0300] {taskinstance.py:2303} INFO - Starting attempt 1 of 1
[2024-05-04T01:28:41.985-0300] {taskinstance.py:2327} INFO - Executing <Task(PythonOperator): task1> on 2024-05-04 04:28:38.637446+00:00
[2024-05-04T01:28:41.990-0300] {standard_task_runner.py:63} INFO - Started process 23899 to run task
[2024-05-04T01:28:41.995-0300] {standard_task_runner.py:90} INFO - Running: ['airflow', 'tasks', 'run', 'Hook_dag', 'task1', 'manual__2024-05-04T04:28:38.637446+00:00', '--job-id', '1131', '--raw', '--subdir', 'DAGS_FOLDER/hook_dag.py', '--cfg-path', '/tmp/tmpcrf95y0d']
[2024-05-04T01:28:41.998-0300] {standard_task_runner.py:91} INFO - Job 1131: Subtask task1
[2024-05-04T01:28:42.227-0300] {task_command.py:426} INFO - Running <TaskInstance: Hook_dag.task1 manual__2024-05-04T04:28:38.637446+00:00 [running]> on host PC-Tilto.
[2024-05-04T01:28:42.625-0300] {taskinstance.py:2644} INFO - Exporting env vars: AIRFLOW_CTX_DAG_OWNER='airflow' AIRFLOW_CTX_DAG_ID='Hook_dag' AIRFLOW_CTX_TASK_ID='task1' AIRFLOW_CTX_EXECUTION_DATE='2024-05-04T04:28:38.637446+00:00' AIRFLOW_CTX_TRY_NUMBER='1' AIRFLOW_CTX_DAG_RUN_ID='manual__2024-05-04T04:28:38.637446+00:00'
[2024-05-04T01:28:42.626-0300] {taskinstance.py:430} INFO - ::endgroup::
[2024-05-04T01:28:42.637-0300] {taskinstance.py:441} INFO - ::group::Post task execution logs
[2024-05-04T01:28:42.638-0300] {taskinstance.py:2890} ERROR - Task failed with exception
Traceback (most recent call last):
  File "/usr/local/lib/python3.10/dist-packages/airflow/models/taskinstance.py", line 465, in _execute_task
    result = _execute_callable(context=context, **execute_callable_kwargs)
  File "/usr/local/lib/python3.10/dist-packages/airflow/models/taskinstance.py", line 432, in _execute_callable
    return execute_callable(context=context, **execute_callable_kwargs)
  File "/usr/local/lib/python3.10/dist-packages/airflow/models/baseoperator.py", line 400, in wrapper
    return func(self, *args, **kwargs)
  File "/usr/local/lib/python3.10/dist-packages/airflow/operators/python.py", line 235, in execute
    return_value = self.execute_callable()
  File "/usr/local/lib/python3.10/dist-packages/airflow/operators/python.py", line 252, in execute_callable
    return self.python_callable(*self.op_args, **self.op_kwargs)
  File "/mnt/c/Users/Tilto/Desktop/Work/Airflow/dags/hook_dag.py", line 10, in read_data
    pghook.copy_expert(
NameError: name 'pghook' is not defined
[2024-05-04T01:28:42.658-0300] {taskinstance.py:1205} INFO - Marking task as FAILED. dag_id=Hook_dag, task_id=task1, execution_date=20240504T042838, start_date=20240504T042841, end_date=20240504T042842
[2024-05-04T01:28:42.753-0300] {standard_task_runner.py:110} ERROR - Failed to execute job 1131 for task task1 (name 'pghook' is not defined; 23899)
[2024-05-04T01:28:42.777-0300] {local_task_job_runner.py:240} INFO - Task exited with return code 1
[2024-05-04T01:28:42.803-0300] {taskinstance.py:3482} INFO - 0 downstream tasks scheduled from follow-on schedule check
[2024-05-04T01:28:42.826-0300] {local_task_job_runner.py:222} INFO - ::endgroup::
