[2024-05-04T01:45:51.931-0300] {local_task_job_runner.py:120} INFO - ::group::Pre task execution logs
[2024-05-04T01:45:51.957-0300] {taskinstance.py:2073} INFO - Dependencies all met for dep_context=non-requeueable deps ti=<TaskInstance: Hook_dag.task1 manual__2024-05-04T04:28:38.637446+00:00 [queued]>
[2024-05-04T01:45:51.969-0300] {taskinstance.py:2073} INFO - Dependencies all met for dep_context=requeueable deps ti=<TaskInstance: Hook_dag.task1 manual__2024-05-04T04:28:38.637446+00:00 [queued]>
[2024-05-04T01:45:51.969-0300] {taskinstance.py:2303} INFO - Starting attempt 2 of 2
[2024-05-04T01:45:52.001-0300] {taskinstance.py:2327} INFO - Executing <Task(PythonOperator): task1> on 2024-05-04 04:28:38.637446+00:00
[2024-05-04T01:45:52.003-0300] {standard_task_runner.py:63} INFO - Started process 3685 to run task
[2024-05-04T01:45:52.006-0300] {standard_task_runner.py:90} INFO - Running: ['airflow', 'tasks', 'run', 'Hook_dag', 'task1', 'manual__2024-05-04T04:28:38.637446+00:00', '--job-id', '1138', '--raw', '--subdir', 'DAGS_FOLDER/hook_dag.py', '--cfg-path', '/tmp/tmp1mnt3qws']
[2024-05-04T01:45:52.007-0300] {standard_task_runner.py:91} INFO - Job 1138: Subtask task1
[2024-05-04T01:45:52.088-0300] {task_command.py:426} INFO - Running <TaskInstance: Hook_dag.task1 manual__2024-05-04T04:28:38.637446+00:00 [running]> on host PC-Tilto.
[2024-05-04T01:45:52.286-0300] {taskinstance.py:2644} INFO - Exporting env vars: AIRFLOW_CTX_DAG_OWNER='airflow' AIRFLOW_CTX_DAG_ID='Hook_dag' AIRFLOW_CTX_TASK_ID='task1' AIRFLOW_CTX_EXECUTION_DATE='2024-05-04T04:28:38.637446+00:00' AIRFLOW_CTX_TRY_NUMBER='2' AIRFLOW_CTX_DAG_RUN_ID='manual__2024-05-04T04:28:38.637446+00:00'
[2024-05-04T01:45:52.287-0300] {taskinstance.py:430} INFO - ::endgroup::
[2024-05-04T01:45:52.297-0300] {postgres.py:175} INFO - Running copy expert: COPY (SELECT * FROM characters) TO stdout WITH CSV HEADER, filename: /mnt/c/Users/Tilto/Desktop/Work/Airflow/data/characters.csv
[2024-05-04T01:45:52.312-0300] {taskinstance.py:441} INFO - ::group::Post task execution logs
[2024-05-04T01:45:52.324-0300] {taskinstance.py:2890} ERROR - Task failed with exception
Traceback (most recent call last):
  File "/usr/local/lib/python3.10/dist-packages/airflow/models/taskinstance.py", line 465, in _execute_task
    result = _execute_callable(context=context, **execute_callable_kwargs)
  File "/usr/local/lib/python3.10/dist-packages/airflow/models/taskinstance.py", line 432, in _execute_callable
    return execute_callable(context=context, **execute_callable_kwargs)
  File "/usr/local/lib/python3.10/dist-packages/airflow/models/baseoperator.py", line 400, in wrapper
    return func(self, *args, **kwargs)
  File "/usr/local/lib/python3.10/dist-packages/airflow/operators/python.py", line 235, in execute
    return_value = self.execute_callable()
  File "/usr/local/lib/python3.10/dist-packages/airflow/operators/python.py", line 252, in execute_callable
    return self.python_callable(*self.op_args, **self.op_kwargs)
  File "/mnt/c/Users/Tilto/Desktop/Work/Airflow/dags/hook_dag.py", line 11, in read_data
    pghook.copy_expert(
  File "/usr/local/lib/python3.10/dist-packages/airflow/providers/postgres/hooks/postgres.py", line 180, in copy_expert
    with open(filename, "r+") as file, closing(self.get_conn()) as conn, closing(conn.cursor()) as cur:
  File "/usr/local/lib/python3.10/dist-packages/airflow/providers/postgres/hooks/postgres.py", line 131, in get_conn
    conn = deepcopy(self.connection or self.get_connection(conn_id))
  File "/usr/local/lib/python3.10/dist-packages/airflow/hooks/base.py", line 83, in get_connection
    conn = Connection.get_connection_from_secrets(conn_id)
  File "/usr/local/lib/python3.10/dist-packages/airflow/models/connection.py", line 519, in get_connection_from_secrets
    raise AirflowNotFoundException(f"The conn_id `{conn_id}` isn't defined")
airflow.exceptions.AirflowNotFoundException: The conn_id `PG_SWORDBLAST` isn't defined
[2024-05-04T01:45:52.334-0300] {taskinstance.py:1205} INFO - Marking task as FAILED. dag_id=Hook_dag, task_id=task1, execution_date=20240504T042838, start_date=20240504T044551, end_date=20240504T044552
[2024-05-04T01:45:52.371-0300] {standard_task_runner.py:110} ERROR - Failed to execute job 1138 for task task1 (The conn_id `PG_SWORDBLAST` isn't defined; 3685)
[2024-05-04T01:45:52.380-0300] {local_task_job_runner.py:240} INFO - Task exited with return code 1
[2024-05-04T01:45:52.404-0300] {taskinstance.py:3482} INFO - 0 downstream tasks scheduled from follow-on schedule check
[2024-05-04T01:45:52.423-0300] {local_task_job_runner.py:222} INFO - ::endgroup::
