[2024-05-06T18:51:12.605-0300] {local_task_job_runner.py:120} INFO - ::group::Pre task execution logs
[2024-05-06T18:51:12.636-0300] {taskinstance.py:2073} INFO - Dependencies all met for dep_context=non-requeueable deps ti=<TaskInstance: Hook_dag.task1 manual__2024-05-06T21:51:09.822558+00:00 [queued]>
[2024-05-06T18:51:12.663-0300] {taskinstance.py:2073} INFO - Dependencies all met for dep_context=requeueable deps ti=<TaskInstance: Hook_dag.task1 manual__2024-05-06T21:51:09.822558+00:00 [queued]>
[2024-05-06T18:51:12.664-0300] {taskinstance.py:2303} INFO - Starting attempt 1 of 1
[2024-05-06T18:51:12.764-0300] {taskinstance.py:2327} INFO - Executing <Task(PythonOperator): task1> on 2024-05-06 21:51:09.822558+00:00
[2024-05-06T18:51:12.767-0300] {standard_task_runner.py:63} INFO - Started process 8196 to run task
[2024-05-06T18:51:12.772-0300] {standard_task_runner.py:90} INFO - Running: ['airflow', 'tasks', 'run', 'Hook_dag', 'task1', 'manual__2024-05-06T21:51:09.822558+00:00', '--job-id', '1160', '--raw', '--subdir', 'DAGS_FOLDER/hook_dag.py', '--cfg-path', '/tmp/tmpj9x2sfvm']
[2024-05-06T18:51:12.774-0300] {standard_task_runner.py:91} INFO - Job 1160: Subtask task1
[2024-05-06T18:51:13.025-0300] {task_command.py:426} INFO - Running <TaskInstance: Hook_dag.task1 manual__2024-05-06T21:51:09.822558+00:00 [running]> on host PC-Tilto.
[2024-05-06T18:51:13.291-0300] {taskinstance.py:2644} INFO - Exporting env vars: AIRFLOW_CTX_DAG_OWNER='airflow' AIRFLOW_CTX_DAG_ID='Hook_dag' AIRFLOW_CTX_TASK_ID='task1' AIRFLOW_CTX_EXECUTION_DATE='2024-05-06T21:51:09.822558+00:00' AIRFLOW_CTX_TRY_NUMBER='1' AIRFLOW_CTX_DAG_RUN_ID='manual__2024-05-06T21:51:09.822558+00:00'
[2024-05-06T18:51:13.292-0300] {taskinstance.py:430} INFO - ::endgroup::
[2024-05-06T18:51:13.312-0300] {postgres.py:175} INFO - Running copy expert: COPY (SELECT * FROM characters) TO stdout WITH CSV HEADER, filename: /mnt/c/Users/Tilto/Desktop/Work/Airflow/data/characters.csv
[2024-05-06T18:51:13.333-0300] {base.py:84} INFO - Using connection ID 'PG_SWORDBLAST' for task execution.
[2024-05-06T18:53:26.040-0300] {taskinstance.py:441} INFO - ::group::Post task execution logs
[2024-05-06T18:53:26.041-0300] {taskinstance.py:2890} ERROR - Task failed with exception
Traceback (most recent call last):
  File "/usr/local/lib/python3.10/dist-packages/airflow/models/taskinstance.py", line 465, in _execute_task
    result = _execute_callable(context=context, **execute_callable_kwargs)
  File "/usr/local/lib/python3.10/dist-packages/airflow/models/taskinstance.py", line 432, in _execute_callable
    return execute_callable(context=context, **execute_callable_kwargs)
  File "/usr/local/lib/python3.10/dist-packages/airflow/models/baseoperator.py", line 400, in wrapper
    return func(self, *args, **kwargs)
  File "/usr/local/lib/python3.10/dist-packages/airflow/operators/python.py", line 235, in execute
    return_value = self.execute_callable()
  File "/usr/local/lib/python3.10/dist-packages/airflow/operators/python.py", line 252, in execute_callable
    return self.python_callable(*self.op_args, **self.op_kwargs)
  File "/mnt/c/Users/Tilto/Desktop/Work/Airflow/dags/hook_dag.py", line 11, in read_data
    pghook.copy_expert(
  File "/usr/local/lib/python3.10/dist-packages/airflow/providers/postgres/hooks/postgres.py", line 180, in copy_expert
    with open(filename, "r+") as file, closing(self.get_conn()) as conn, closing(conn.cursor()) as cur:
  File "/usr/local/lib/python3.10/dist-packages/airflow/providers/postgres/hooks/postgres.py", line 161, in get_conn
    self.conn = psycopg2.connect(**conn_args)
  File "/usr/local/lib/python3.10/dist-packages/psycopg2/__init__.py", line 122, in connect
    conn = _connect(dsn, connection_factory=connection_factory, **kwasync)
psycopg2.OperationalError: connection to server at "172.16.2.201", port 5432 failed: Connection timed out
	Is the server running on that host and accepting TCP/IP connections?

[2024-05-06T18:53:26.057-0300] {taskinstance.py:1205} INFO - Marking task as FAILED. dag_id=Hook_dag, task_id=task1, execution_date=20240506T215109, start_date=20240506T215112, end_date=20240506T215326
[2024-05-06T18:53:26.095-0300] {standard_task_runner.py:110} ERROR - Failed to execute job 1160 for task task1 (connection to server at "172.16.2.201", port 5432 failed: Connection timed out
	Is the server running on that host and accepting TCP/IP connections?
; 8196)
[2024-05-06T18:53:26.118-0300] {local_task_job_runner.py:240} INFO - Task exited with return code 1
[2024-05-06T18:53:26.143-0300] {taskinstance.py:3482} INFO - 0 downstream tasks scheduled from follow-on schedule check
[2024-05-06T18:53:26.167-0300] {local_task_job_runner.py:222} INFO - ::endgroup::
