[2024-05-02T19:33:14.598-0300] {local_task_job_runner.py:120} INFO - ::group::Pre task execution logs
[2024-05-02T19:33:14.626-0300] {taskinstance.py:2073} INFO - Dependencies all met for dep_context=non-requeueable deps ti=<TaskInstance: a_primeira_DAG_v1.hello scheduled__2023-10-14T00:00:00+00:00 [queued]>
[2024-05-02T19:33:14.642-0300] {taskinstance.py:2073} INFO - Dependencies all met for dep_context=requeueable deps ti=<TaskInstance: a_primeira_DAG_v1.hello scheduled__2023-10-14T00:00:00+00:00 [queued]>
[2024-05-02T19:33:14.643-0300] {taskinstance.py:2303} INFO - Starting attempt 1 of 1
[2024-05-02T19:33:14.680-0300] {taskinstance.py:2327} INFO - Executing <Task(BashOperator): hello> on 2023-10-14 00:00:00+00:00
[2024-05-02T19:33:14.682-0300] {standard_task_runner.py:63} INFO - Started process 6413 to run task
[2024-05-02T19:33:14.684-0300] {standard_task_runner.py:90} INFO - Running: ['airflow', 'tasks', 'run', 'a_primeira_DAG_v1', 'hello', 'scheduled__2023-10-14T00:00:00+00:00', '--job-id', '437', '--raw', '--subdir', 'DAGS_FOLDER/primeira_dagv1.py', '--cfg-path', '/tmp/tmpp8_y002f']
[2024-05-02T19:33:14.686-0300] {standard_task_runner.py:91} INFO - Job 437: Subtask hello
[2024-05-02T19:33:14.755-0300] {task_command.py:426} INFO - Running <TaskInstance: a_primeira_DAG_v1.hello scheduled__2023-10-14T00:00:00+00:00 [running]> on host PC-Tilto.
[2024-05-02T19:33:14.814-0300] {local_task_job_runner.py:222} INFO - ::endgroup::
[2024-05-02T19:33:14.816-0300] {process_utils.py:132} INFO - Sending Signals.SIGTERM to group 6413. PIDs of all processes in the group: [6413]
[2024-05-02T19:33:14.817-0300] {process_utils.py:87} INFO - Sending the signal Signals.SIGTERM to group 6413
[2024-05-02T19:33:14.817-0300] {taskinstance.py:2607} ERROR - Received SIGTERM. Terminating subprocesses.
[2024-05-02T19:33:14.818-0300] {subprocess.py:104} INFO - Sending SIGTERM signal to process group
[2024-05-02T19:33:14.832-0300] {taskinstance.py:2890} ERROR - Task failed with exception
Traceback (most recent call last):
  File "/usr/local/lib/python3.10/dist-packages/airflow/models/taskinstance.py", line 2476, in _run_raw_task
    self._execute_task_with_callbacks(context, test_mode, session=session)
  File "/usr/local/lib/python3.10/dist-packages/airflow/models/taskinstance.py", line 2615, in _execute_task_with_callbacks
    self.clear_xcom_data()
  File "/usr/local/lib/python3.10/dist-packages/airflow/utils/session.py", line 79, in wrapper
    return func(*args, session=session, **kwargs)
  File "/usr/local/lib/python3.10/dist-packages/airflow/models/taskinstance.py", line 1857, in clear_xcom_data
    self._clear_xcom_data(ti=self, session=session)
  File "/usr/local/lib/python3.10/dist-packages/airflow/api_internal/internal_api_call.py", line 115, in wrapper
    return func(*args, **kwargs)
  File "/usr/local/lib/python3.10/dist-packages/airflow/utils/session.py", line 76, in wrapper
    return func(*args, **kwargs)
  File "/usr/local/lib/python3.10/dist-packages/airflow/models/taskinstance.py", line 1847, in _clear_xcom_data
    XCom.clear(
  File "/usr/local/lib/python3.10/dist-packages/airflow/utils/session.py", line 76, in wrapper
    return func(*args, **kwargs)
  File "/usr/local/lib/python3.10/dist-packages/airflow/api_internal/internal_api_call.py", line 115, in wrapper
    return func(*args, **kwargs)
  File "/usr/local/lib/python3.10/dist-packages/airflow/models/xcom.py", line 654, in clear
    for xcom in query:
  File "/usr/local/lib/python3.10/dist-packages/sqlalchemy/orm/query.py", line 2901, in __iter__
    result = self._iter()
  File "/usr/local/lib/python3.10/dist-packages/sqlalchemy/orm/query.py", line 2916, in _iter
    result = self.session.execute(
  File "/usr/local/lib/python3.10/dist-packages/sqlalchemy/orm/session.py", line 1720, in execute
    result = compile_state_cls.orm_setup_cursor_result(
  File "/usr/local/lib/python3.10/dist-packages/sqlalchemy/orm/context.py", line 349, in orm_setup_cursor_result
    return loading.instances(result, querycontext)
  File "/usr/local/lib/python3.10/dist-packages/sqlalchemy/orm/loading.py", line 69, in instances
    *[
  File "/usr/local/lib/python3.10/dist-packages/sqlalchemy/orm/loading.py", line 70, in <listcomp>
    query_entity.row_processor(context, cursor)
  File "/usr/local/lib/python3.10/dist-packages/sqlalchemy/orm/context.py", line 2631, in row_processor
    _instance = loading._instance_processor(
  File "/usr/local/lib/python3.10/dist-packages/sqlalchemy/orm/loading.py", line 790, in _instance_processor
    path.set(compile_state.attributes, getter_key, getters)
  File "/usr/local/lib/python3.10/dist-packages/sqlalchemy/orm/path_registry.py", line 91, in set
    def set(self, attributes, key, value):
  File "/usr/local/lib/python3.10/dist-packages/airflow/models/taskinstance.py", line 2609, in signal_handler
    raise AirflowTaskTerminated("Task received SIGTERM signal")
airflow.exceptions.AirflowTaskTerminated: Task received SIGTERM signal
[2024-05-02T19:33:14.851-0300] {taskinstance.py:1205} INFO - Marking task as FAILED. dag_id=a_primeira_DAG_v1, task_id=hello, execution_date=20231014T000000, start_date=20240502T223314, end_date=20240502T223314
[2024-05-02T19:33:14.909-0300] {process_utils.py:80} INFO - Process psutil.Process(pid=6413, status='terminated', exitcode=2, started='19:33:13') (6413) terminated with exit code 2
