[2024-05-03T21:14:33.757-0300] {local_task_job_runner.py:120} INFO - ::group::Pre task execution logs
[2024-05-03T21:14:33.786-0300] {taskinstance.py:2073} INFO - Dependencies all met for dep_context=non-requeueable deps ti=<TaskInstance: dag_exemplo.gera_arquivo manual__2024-05-04T00:14:13.367071+00:00 [queued]>
[2024-05-03T21:14:33.803-0300] {taskinstance.py:2073} INFO - Dependencies all met for dep_context=requeueable deps ti=<TaskInstance: dag_exemplo.gera_arquivo manual__2024-05-04T00:14:13.367071+00:00 [queued]>
[2024-05-03T21:14:33.804-0300] {taskinstance.py:2303} INFO - Starting attempt 1 of 1
[2024-05-03T21:14:33.848-0300] {taskinstance.py:2327} INFO - Executing <Task(PythonOperator): gera_arquivo> on 2024-05-04 00:14:13.367071+00:00
[2024-05-03T21:14:33.851-0300] {standard_task_runner.py:63} INFO - Started process 19570 to run task
[2024-05-03T21:14:33.854-0300] {standard_task_runner.py:90} INFO - Running: ['airflow', 'tasks', 'run', 'dag_exemplo', 'gera_arquivo', 'manual__2024-05-04T00:14:13.367071+00:00', '--job-id', '900', '--raw', '--subdir', 'DAGS_FOLDER/dag_exemplo.py', '--cfg-path', '/tmp/tmplhe1tasl']
[2024-05-03T21:14:33.856-0300] {standard_task_runner.py:91} INFO - Job 900: Subtask gera_arquivo
[2024-05-03T21:14:33.936-0300] {task_command.py:426} INFO - Running <TaskInstance: dag_exemplo.gera_arquivo manual__2024-05-04T00:14:13.367071+00:00 [running]> on host PC-Tilto.
[2024-05-03T21:14:34.149-0300] {taskinstance.py:2644} INFO - Exporting env vars: AIRFLOW_CTX_DAG_OWNER='airflow' AIRFLOW_CTX_DAG_ID='dag_exemplo' AIRFLOW_CTX_TASK_ID='gera_arquivo' AIRFLOW_CTX_EXECUTION_DATE='2024-05-04T00:14:13.367071+00:00' AIRFLOW_CTX_TRY_NUMBER='1' AIRFLOW_CTX_DAG_RUN_ID='manual__2024-05-04T00:14:13.367071+00:00'
[2024-05-03T21:14:34.150-0300] {taskinstance.py:430} INFO - ::endgroup::
[2024-05-03T21:14:34.160-0300] {taskinstance.py:441} INFO - ::group::Post task execution logs
[2024-05-03T21:14:34.161-0300] {taskinstance.py:2890} ERROR - Task failed with exception
Traceback (most recent call last):
  File "/usr/local/lib/python3.10/dist-packages/airflow/models/taskinstance.py", line 465, in _execute_task
    result = _execute_callable(context=context, **execute_callable_kwargs)
  File "/usr/local/lib/python3.10/dist-packages/airflow/models/taskinstance.py", line 432, in _execute_callable
    return execute_callable(context=context, **execute_callable_kwargs)
  File "/usr/local/lib/python3.10/dist-packages/airflow/models/baseoperator.py", line 400, in wrapper
    return func(self, *args, **kwargs)
  File "/usr/local/lib/python3.10/dist-packages/airflow/operators/python.py", line 235, in execute
    return_value = self.execute_callable()
  File "/usr/local/lib/python3.10/dist-packages/airflow/operators/python.py", line 252, in execute_callable
    return self.python_callable(*self.op_args, **self.op_kwargs)
  File "/mnt/c/Users/Tilto/Desktop/Work/Airflow/dags/dag_exemplo.py", line 11, in gera_arquivo
    with open(AIRFLOW_HOME + "data/arquivo.txt", "wb") as f:
FileNotFoundError: [Errno 2] No such file or directory: '/mnt/c/Users/Tilto/Desktop/Work/Airflowdata/arquivo.txt'
[2024-05-03T21:14:34.180-0300] {taskinstance.py:1205} INFO - Marking task as FAILED. dag_id=dag_exemplo, task_id=gera_arquivo, execution_date=20240504T001413, start_date=20240504T001433, end_date=20240504T001434
[2024-05-03T21:14:34.220-0300] {standard_task_runner.py:110} ERROR - Failed to execute job 900 for task gera_arquivo ([Errno 2] No such file or directory: '/mnt/c/Users/Tilto/Desktop/Work/Airflowdata/arquivo.txt'; 19570)
[2024-05-03T21:14:34.228-0300] {local_task_job_runner.py:240} INFO - Task exited with return code 1
[2024-05-03T21:14:34.265-0300] {taskinstance.py:3482} INFO - 0 downstream tasks scheduled from follow-on schedule check
[2024-05-03T21:14:34.298-0300] {local_task_job_runner.py:222} INFO - ::endgroup::
