[2024-05-06T19:08:50.928-0300] {local_task_job_runner.py:120} INFO - ::group::Pre task execution logs
[2024-05-06T19:08:50.955-0300] {taskinstance.py:2073} INFO - Dependencies all met for dep_context=non-requeueable deps ti=<TaskInstance: hook_dag.task1 manual__2024-05-06T22:08:47.433014+00:00 [queued]>
[2024-05-06T19:08:50.970-0300] {taskinstance.py:2073} INFO - Dependencies all met for dep_context=requeueable deps ti=<TaskInstance: hook_dag.task1 manual__2024-05-06T22:08:47.433014+00:00 [queued]>
[2024-05-06T19:08:50.971-0300] {taskinstance.py:2303} INFO - Starting attempt 1 of 1
[2024-05-06T19:08:51.008-0300] {taskinstance.py:2327} INFO - Executing <Task(PythonOperator): task1> on 2024-05-06 22:08:47.433014+00:00
[2024-05-06T19:08:51.010-0300] {standard_task_runner.py:63} INFO - Started process 12649 to run task
[2024-05-06T19:08:51.013-0300] {standard_task_runner.py:90} INFO - Running: ['airflow', 'tasks', 'run', 'hook_dag', 'task1', 'manual__2024-05-06T22:08:47.433014+00:00', '--job-id', '1167', '--raw', '--subdir', 'DAGS_FOLDER/hook_dag.py', '--cfg-path', '/tmp/tmpir5bnius']
[2024-05-06T19:08:51.014-0300] {standard_task_runner.py:91} INFO - Job 1167: Subtask task1
[2024-05-06T19:08:51.243-0300] {task_command.py:426} INFO - Running <TaskInstance: hook_dag.task1 manual__2024-05-06T22:08:47.433014+00:00 [running]> on host PC-Tilto.
[2024-05-06T19:08:51.459-0300] {taskinstance.py:2644} INFO - Exporting env vars: AIRFLOW_CTX_DAG_OWNER='airflow' AIRFLOW_CTX_DAG_ID='hook_dag' AIRFLOW_CTX_TASK_ID='task1' AIRFLOW_CTX_EXECUTION_DATE='2024-05-06T22:08:47.433014+00:00' AIRFLOW_CTX_TRY_NUMBER='1' AIRFLOW_CTX_DAG_RUN_ID='manual__2024-05-06T22:08:47.433014+00:00'
[2024-05-06T19:08:51.460-0300] {taskinstance.py:430} INFO - ::endgroup::
[2024-05-06T19:08:51.470-0300] {postgres.py:175} INFO - Running copy expert: COPY (SELECT * FROM characters) TO stdout WITH CSV HEADER, filename: /mnt/c/Users/Tilto/Desktop/Work/Airflow/data/characters.csv
[2024-05-06T19:08:51.488-0300] {base.py:84} INFO - Using connection ID 'PG_SWORDBLAST' for task execution.
[2024-05-06T19:10:42.938-0300] {local_task_job_runner.py:222} INFO - ::endgroup::
[2024-05-06T19:10:42.940-0300] {process_utils.py:132} INFO - Sending Signals.SIGTERM to group 12649. PIDs of all processes in the group: [12649]
[2024-05-06T19:10:42.941-0300] {process_utils.py:87} INFO - Sending the signal Signals.SIGTERM to group 12649
[2024-05-06T19:10:46.392-0300] {local_task_job_runner.py:120} INFO - ::group::Pre task execution logs
[2024-05-06T19:10:46.418-0300] {taskinstance.py:2063} INFO - Dependencies not met for <TaskInstance: hook_dag.task1 manual__2024-05-06T22:08:47.433014+00:00 [running]>, dependency 'Task Instance Not Running' FAILED: Task is in the running state
[2024-05-06T19:10:46.419-0300] {taskinstance.py:2063} INFO - Dependencies not met for <TaskInstance: hook_dag.task1 manual__2024-05-06T22:08:47.433014+00:00 [running]>, dependency 'Task Instance State' FAILED: Task is in the 'running' state.
[2024-05-06T19:10:46.420-0300] {local_task_job_runner.py:163} INFO - Task is not able to be run
[2024-05-06T19:11:00.759-0300] {taskinstance.py:2607} ERROR - Received SIGTERM. Terminating subprocesses.
[2024-05-06T19:11:00.760-0300] {taskinstance.py:441} INFO - ::group::Post task execution logs
[2024-05-06T19:11:00.770-0300] {taskinstance.py:2890} ERROR - Task failed with exception
Traceback (most recent call last):
  File "/usr/local/lib/python3.10/dist-packages/airflow/providers/postgres/hooks/postgres.py", line 180, in copy_expert
    with open(filename, "r+") as file, closing(self.get_conn()) as conn, closing(conn.cursor()) as cur:
  File "/usr/local/lib/python3.10/dist-packages/airflow/providers/postgres/hooks/postgres.py", line 161, in get_conn
    self.conn = psycopg2.connect(**conn_args)
  File "/usr/local/lib/python3.10/dist-packages/psycopg2/__init__.py", line 122, in connect
    conn = _connect(dsn, connection_factory=connection_factory, **kwasync)
psycopg2.OperationalError: connection to server at "172.16.2.201", port 5432 failed: Connection timed out
	Is the server running on that host and accepting TCP/IP connections?


During handling of the above exception, another exception occurred:

Traceback (most recent call last):
  File "/usr/local/lib/python3.10/dist-packages/airflow/models/taskinstance.py", line 465, in _execute_task
    result = _execute_callable(context=context, **execute_callable_kwargs)
  File "/usr/local/lib/python3.10/dist-packages/airflow/models/taskinstance.py", line 432, in _execute_callable
    return execute_callable(context=context, **execute_callable_kwargs)
  File "/usr/local/lib/python3.10/dist-packages/airflow/models/baseoperator.py", line 400, in wrapper
    return func(self, *args, **kwargs)
  File "/usr/local/lib/python3.10/dist-packages/airflow/operators/python.py", line 235, in execute
    return_value = self.execute_callable()
  File "/usr/local/lib/python3.10/dist-packages/airflow/operators/python.py", line 252, in execute_callable
    return self.python_callable(*self.op_args, **self.op_kwargs)
  File "/mnt/c/Users/Tilto/Desktop/Work/Airflow/dags/hook_dag.py", line 11, in read_data
    pghook.copy_expert(
  File "/usr/local/lib/python3.10/dist-packages/airflow/providers/postgres/hooks/postgres.py", line 180, in copy_expert
    with open(filename, "r+") as file, closing(self.get_conn()) as conn, closing(conn.cursor()) as cur:
  File "/usr/local/lib/python3.10/dist-packages/airflow/models/taskinstance.py", line 2609, in signal_handler
    raise AirflowTaskTerminated("Task received SIGTERM signal")
airflow.exceptions.AirflowTaskTerminated: Task received SIGTERM signal
[2024-05-06T19:11:00.779-0300] {taskinstance.py:1205} INFO - Marking task as FAILED. dag_id=hook_dag, task_id=task1, execution_date=20240506T220847, start_date=20240506T220850, end_date=20240506T221100
